Workbook

Sheet Roll-up
B1: Property: | C1: Portfolio Roll-up
B2: Address: | E2: 12 | F2: 1 | G2: 11 | H2: 12 | I2: 1 | J2: 2 | K2: 3 | L2: 4 | M2: 5 | N2: 6 | O2: 7 | P2: 8 | Q2: 9 | R2: 10 | S2: 11 | T2: 12 | U2: 1 | V2: 2 | W2: 3 | X2: 4 | Y2: 5 | Z2: 6 | AA2: 7 | AB2: 8 | AC2: 9 | AD2: 10 | AE2: 11 | AF2: 12 | AG2: 1 | AH2: 2 | AI2: 3
E3: 1899 | F3: 2023 | G3: 2023 | H3: 2023 | I3: 2024 | J3: 2024 | K3: 2024 | L3: 2024 | M3: 2024 | N3: 2024 | O3: 2024 | P3: 2024 | Q3: 2024 | R3: 2024 | S3: 2024 | T3: 2024 | U3: 2025 | V3: 2025 | W3: 2025 | X3: 2025 | Y3: 2025 | Z3: 2025 | AA3: 2025 | AB3: 2025 | AC3: 2025 | AD3: 2025 | AE3: 2025 | AF3: 2025 | AG3: 2026 | AH3: 2026 | AI3: 2026
B6: Utility Items | C6: Utility Provider | D6: Account Number | E6: Dec-99 | F6: Jan-23 | G6: Nov-23 | H6: Dec-23 | I6: Jan-24 | J6: Feb-24 | K6: Mar-24 | L6: Apr-24 | M6: May-24 | N6: Jun-24 | O6: Jul-24 | P6: Aug-24 | Q6: Sep-24 | R6: Oct-24 | S6: Nov-24 | T6: Dec-24 | U6: Jan-25 | V6: Feb-25 | W6: Mar-25 | X6: Apr-25 | Y6: May-25 | Z6: Jun-25 | AA6: Jul-25 | AB6: Aug-25 | AC6: Sep-25 | AD6: Oct-25 | AE6: Nov-25 | AF6: Dec-25 | AG6: Jan-26 | AH6: Feb-26 | AI6: Mar-26 | AJ6: Total | AK6: Comments
B8: Utility Bills | E8: Dec-99 | F8: Jan-23 | G8: Nov-23 | H8: Dec-23 | I8: Jan-24 | J8: Feb-24 | K8: Mar-24 | L8: Apr-24 | M8: May-24 | N8: Jun-24 | O8: Jul-24 | P8: Aug-24 | Q8: Sep-24 | R8: Oct-24 | S8: Nov-24 | T8: Dec-24 | U8: Jan-25 | V8: Feb-25 | W8: Mar-25 | X8: Apr-25 | Y8: May-25 | Z8: Jun-25 | AA8: Jul-25 | AB8: Aug-25 | AC8: Sep-25 | AD8: Oct-25 | AE8: Nov-25 | AF8: Dec-25 | AG8: Jan-26 | AH8: Feb-26 | AI8: Mar-26 | AJ8: Total
B9: Gas | E9: ='Agave Village (ag011)'!E62+'Agave Village LLC'!E51+'Brookhaven Estates (bo260)'!E44+'Brookhaven RV Resort'!E40+'Courtly Manor'!E33+'Courtly Manor Park (co669)'!E34+'Cross Creek RV'!E129+'Cross Creek RV Resort (cr994)'!E135+'El Rio De Oro (el289)'!E31+'El Rio del Oro'!E34+'Endless Summer RV Resort'!E52+'Endless Summer RV Resort (en079'!E44+Evergreen!E31+'Far Horizons'!E31+'Far Horizons (fa105)'!E31+'Floridian Sandalwood (fl356)'!E28+'Floridian Sandalwood MHC'!E32+Glenhaven!E36+'Glenhaven Estates (gl317)'!E36+'Harbor Lights (ha310)'!E37+'Harbor Lights MHC'!E35+'Harvest Gate'!E45+'Hunter Run RV Estates'!E86+'Hunters Run RV Estates (hu116)'!E199+'Jade Isle (ja068)'!E28+'Jade Isle MHC'!E30+'Kakusha Estates (ka045)'!E34+'Kakusha MHC'!E33+'Lakeside Village'!E39+'Lakeside Village (la482)'!E41+'Lakewood Village (la481)'!E100+'Lakewood Village MHC LLC'!E120+'Maple Corner'!E53+'Maple Corner (ma490)'!E43+'Marlboro Court (ma489)'!E31+'Marlboro Court MHC LLC'!E31+'May Manor'!E135+'May Manor (ma488)'!E67+'Mobiland by the Sea (mo320)'!E36+'Mobiland By The Sea MHC'!E37+'Moss Landing'!E64+'Moss Landing (mo321)'!E56+'Oak Springs'!E68+'Oak Springs MHC (oa150)'!E44+'Orange Manor East'!E33+'Orange Manor East (or125)'!E36+'Pacific Manor'!E42+'Pacific Manor (pa602)'!E44+Parkhaven!E99+Ridgecrest!E49+Riverest!E43+'Riverview MHRV LLC'!E46+Rosehaven!E111+'Sanctuary RV Resort'!E223+'Shadow Mountain MHC'!E30+Springhaven!E30+'Star Valley Ranch'!E41+Sunhaven!E37+'Sunny Grove'!E36+Tarponaire!E40+'Val Vista RV Resort'!E69+'Webster RV Resort LLC'!E56+'Wekiva Falls RV Resort'!E80+'West Jupiter RV Resort'!E37+'Western Way RV Resort LLC'!E129 | F9: ='Agave Village (ag011)'!F62+'Agave Village LLC'!F51+'Brookhaven Estates (bo260)'!F44+'Brookhaven RV Resort'!F40+'Courtly Manor'!F33+'Courtly Manor Park (co669)'!F34+'Cross Creek RV'!F129+'Cross Creek RV Resort (cr994)'!F135+'El Rio De Oro (el289)'!F31+'El Rio del Oro'!F34+'Endless Summer RV Resort'!F52+'Endless Summer RV Resort (en079'!F44+Evergreen!F31+'Far Horizons'!F31+'Far Horizons (fa105)'!F31+'Floridian Sandalwood (fl356)'!F28+'Floridian Sandalwood MHC'!F32+Glenhaven!F36+'Glenhaven Estates (gl317)'!F36+'Harbor Lights (ha310)'!F37+'Harbor Lights MHC'!F35+'Harvest Gate'!F45+'Hunter Run RV Estates'!F86+'Hunters Run RV Estates (hu116)'!F199+'Jade Isle (ja068)'!F28+'Jade Isle MHC'!F30+'Kakusha Estates (ka045)'!F34+'Kakusha MHC'!F33+'Lakeside Village'!F39+'Lakeside Village (la482)'!F41+'Lakewood Village (la481)'!F100+'Lakewood Village MHC LLC'!F120+'Maple Corner'!F53+'Maple Corner (ma490)'!F43+'Marlboro Court (ma489)'!F31+'Marlboro Court MHC LLC'!F31+'May Manor'!F135+'May Manor (ma488)'!F67+'Mobiland by the Sea (mo320)'!F36+'Mobiland By The Sea MHC'!F37+'Moss Landing'!F64+'Moss Landing (mo321)'!F56+'Oak Springs'!F68+'Oak Springs MHC (oa150)'!F44+'Orange Manor East'!F33+'Orange Manor East (or125)'!F36+'Pacific Manor'!F42+'Pacific Manor (pa602)'!F44+Parkhaven!F99+Ridgecrest!F49+Riverest!F43+'Riverview MHRV LLC'!F46+Rosehaven!F111+'Sanctuary RV Resort'!F223+'Shadow Mountain MHC'!F30+Springhaven!F30+'Star Valley Ranch'!F41+Sunhaven!F37+'Sunny Grove'!F36+Tarponaire!F40+'Val Vista RV Resort'!F69+'Webster RV Resort LLC'!F56+'Wekiva Falls RV Resort'!F80+'West Jupiter RV Resort'!F37+'Western Way RV Resort LLC'!F129 | G9: ='Agave Village (ag011)'!G62+'Agave Village LLC'!G51+'Brookhaven Estates (bo260)'!G44+'Brookhaven RV Resort'!G40+'Courtly Manor'!G33+'Courtly Manor Park (co669)'!G34+'Cross Creek RV'!G129+'Cross Creek RV Resort (cr994)'!G135+'El Rio De Oro (el289)'!G31+'El Rio del Oro'!G34+'Endless Summer RV Resort'!G52+'Endless Summer RV Resort (en079'!G44+Evergreen!G31+'Far Horizons'!G31+'Far Horizons (fa105)'!G31+'Floridian Sandalwood (fl356)'!G28+'Floridian Sandalwood MHC'!G32+Glenhaven!G36+'Glenhaven Estates (gl317)'!G36+'Harbor Lights (ha310)'!G37+'Harbor Lights MHC'!G35+'Harvest Gate'!G45+'Hunter Run RV Estates'!G86+'Hunters Run RV Estates (hu116)'!G199+'Jade Isle (ja068)'!G28+'Jade Isle MHC'!G30+'Kakusha Estates (ka045)'!G34+'Kakusha MHC'!G33+'Lakeside Village'!G39+'Lakeside Village (la482)'!G41+'Lakewood Village (la481)'!G100+'Lakewood Village MHC LLC'!G120+'Maple Corner'!G53+'Maple Corner (ma490)'!G43+'Marlboro Court (ma489)'!G31+'Marlboro Court MHC LLC'!G31+'May Manor'!G135+'May Manor (ma488)'!G67+'Mobiland by the Sea (mo320)'!G36+'Mobiland By The Sea MHC'!G37+'Moss Landing'!G64+'Moss Landing (mo321)'!G56+'Oak Springs'!G68+'Oak Springs MHC (oa150)'!G44+'Orange Manor East'!G33+'Orange Manor East (or125)'!G36+'Pacific Manor'!G42+'Pacific Manor (pa602)'!G44+Parkhaven!G99+Ridgecrest!G49+Riverest!G43+'Riverview MHRV LLC'!G46+Rosehaven!G111+'Sanctuary RV Resort'!G223+'Shadow Mountain MHC'!G30+Springhaven!G30+'Star Valley Ranch'!G41+Sunhaven!G37+'Sunny Grove'!G36+Tarponaire!G40+'Val Vista RV Resort'!G69+'Webster RV Resort LLC'!G56+'Wekiva Falls RV Resort'!G80+'West Jupiter RV Resort'!G37+'Western Way RV Resort LLC'!G129 | H9: ='Agave Village (ag011)'!H62+'Agave Village LLC'!H51+'Brookhaven Estates (bo260)'!H44+'Brookhaven RV Resort'!H40+'Courtly Manor'!H33+'Courtly Manor Park (co669)'!H34+'Cross Creek RV'!H129+'Cross Creek RV Resort (cr994)'!H135+'El Rio De Oro (el289)'!H31+'El Rio del Oro'!H34+'Endless Summer RV Resort'!H52+'Endless Summer RV Resort (en079'!H44+Evergreen!H31+'Far Horizons'!H31+'Far Horizons (fa105)'!H31+'Floridian Sandalwood (fl356)'!H28+'Floridian Sandalwood MHC'!H32+Glenhaven!H36+'Glenhaven Estates (gl317)'!H36+'Harbor Lights (ha310)'!H37+'Harbor Lights MHC'!H35+'Harvest Gate'!H45+'Hunter Run RV Estates'!H86+'Hunters Run RV Estates (hu116)'!H199+'Jade Isle (ja068)'!H28+'Jade Isle MHC'!H30+'Kakusha Estates (ka045)'!H34+'Kakusha MHC'!H33+'Lakeside Village'!H39+'Lakeside Village (la482)'!H41+'Lakewood Village (la481)'!H100+'Lakewood Village MHC LLC'!H120+'Maple Corner'!H53+'Maple Corner (ma490)'!H43+'Marlboro Court (ma489)'!H31+'Marlboro Court MHC LLC'!H31+'May Manor'!H135+'May Manor (ma488)'!H67+'Mobiland by the Sea (mo320)'!H36+'Mobiland By The Sea MHC'!H37+'Moss Landing'!H64+'Moss Landing (mo321)'!H56+'Oak Springs'!H68+'Oak Springs MHC (oa150)'!H44+'Orange Manor East'!H33+'Orange Manor East (or125)'!H36+'Pacific Manor'!H42+'Pacific Manor (pa602)'!H44+Parkhaven!H99+Ridgecrest!H49+Riverest!H43+'Riverview MHRV LLC'!H46+Rosehaven!H111+'Sanctuary RV Resort'!H223+'Shadow Mountain MHC'!H30+Springhaven!H30+'Star Valley Ranch'!H41+Sunhaven!H37+'Sunny Grove'!H36+Tarponaire!H40+'Val Vista RV Resort'!H69+'Webster RV Resort LLC'!H56+'Wekiva Falls RV Resort'!H80+'West Jupiter RV Resort'!H37+'Western Way RV Resort LLC'!H129 | I9: ='Agave Village (ag011)'!I62+'Agave Village LLC'!I51+'Brookhaven Estates (bo260)'!I44+'Brookhaven RV Resort'!I40+'Courtly Manor'!I33+'Courtly Manor Park (co669)'!I34+'Cross Creek RV'!I129+'Cross Creek RV Resort (cr994)'!I135+'El Rio De Oro (el289)'!I31+'El Rio del Oro'!I34+'Endless Summer RV Resort'!I52+'Endless Summer RV Resort (en079'!I44+Evergreen!I31+'Far Horizons'!I31+'Far Horizons (fa105)'!I31+'Floridian Sandalwood (fl356)'!I28+'Floridian Sandalwood MHC'!I32+Glenhaven!I36+'Glenhaven Estates (gl317)'!I36+'Harbor Lights (ha310)'!I37+'Harbor Lights MHC'!I35+'Harvest Gate'!I45+'Hunter Run RV Estates'!I86+'Hunters Run RV Estates (hu116)'!I199+'Jade Isle (ja068)'!I28+'Jade Isle MHC'!I30+'Kakusha Estates (ka045)'!I34+'Kakusha MHC'!I33+'Lakeside Village'!I39+'Lakeside Village (la482)'!I41+'Lakewood Village (la481)'!I100+'Lakewood Village MHC LLC'!I120+'Maple Corner'!I53+'Maple Corner (ma490)'!I43+'Marlboro Court (ma489)'!I31+'Marlboro Court MHC LLC'!I31+'May Manor'!I135+'May Manor (ma488)'!I67+'Mobiland by the Sea (mo320)'!I36+'Mobiland By The Sea MHC'!I37+'Moss Landing'!I64+'Moss Landing (mo321)'!I56+'Oak Springs'!I68+'Oak Springs MHC (oa150)'!I44+'Orange Manor East'!I33+'Orange Manor East (or125)'!I36+'Pacific Manor'!I42+'Pacific Manor (pa602)'!I44+Parkhaven!I99+Ridgecrest!I49+Riverest!I43+'Riverview MHRV LLC'!I46+Rosehaven!I111+'Sanctuary RV Resort'!I223+'Shadow Mountain MHC'!I30+Springhaven!I30+'Star Valley Ranch'!I41+Sunhaven!I37+'Sunny Grove'!I36+Tarponaire!I40+'Val Vista RV Resort'!I69+'Webster RV Resort LLC'!I56+'Wekiva Falls RV Resort'!I80+'West Jupiter RV Resort'!I37+'Western Way RV Resort LLC'!I129 | J9: ='Agave Village (ag011)'!J62+'Agave Village LLC'!J51+'Brookhaven Estates (bo260)'!J44+'Brookhaven RV Resort'!J40+'Courtly Manor'!J33+'Courtly Manor Park (co669)'!J34+'Cross Creek RV'!J129+'Cross Creek RV Resort (cr994)'!J135+'El Rio De Oro (el289)'!J31+'El Rio del Oro'!J34+'Endless Summer RV Resort'!J52+'Endless Summer RV Resort (en079'!J44+Evergreen!J31+'Far Horizons'!J31+'Far Horizons (fa105)'!J31+'Floridian Sandalwood (fl356)'!J28+'Floridian Sandalwood MHC'!J32+Glenhaven!J36+'Glenhaven Estates (gl317)'!J36+'Harbor Lights (ha310)'!J37+'Harbor Lights MHC'!J35+'Harvest Gate'!J45+'Hunter Run RV Estates'!J86+'Hunters Run RV Estates (hu116)'!J199+'Jade Isle (ja068)'!J28+'Jade Isle MHC'!J30+'Kakusha Estates (ka045)'!J34+'Kakusha MHC'!J33+'Lakeside Village'!J39+'Lakeside Village (la482)'!J41+'Lakewood Village (la481)'!J100+'Lakewood Village MHC LLC'!J120+'Maple Corner'!J53+'Maple Corner (ma490)'!J43+'Marlboro Court (ma489)'!J31+'Marlboro Court MHC LLC'!J31+'May Manor'!J135+'May Manor (ma488)'!J67+'Mobiland by the Sea (mo320)'!J36+'Mobiland By The Sea MHC'!J37+'Moss Landing'!J64+'Moss Landing (mo321)'!J56+'Oak Springs'!J68+'Oak Springs MHC (oa150)'!J44+'Orange Manor East'!J33+'Orange Manor East (or125)'!J36+'Pacific Manor'!J42+'Pacific Manor (pa602)'!J44+Parkhaven!J99+Ridgecrest!J49+Riverest!J43+'Riverview MHRV LLC'!J46+Rosehaven!J111+'Sanctuary RV Resort'!J223+'Shadow Mountain MHC'!J30+Springhaven!J30+'Star Valley Ranch'!J41+Sunhaven!J37+'Sunny Grove'!J36+Tarponaire!J40+'Val Vista RV Resort'!J69+'Webster RV Resort LLC'!J56+'Wekiva Falls RV Resort'!J80+'West Jupiter RV Resort'!J37+'Western Way RV Resort LLC'!J129 | K9: ='Agave Village (ag011)'!K62+'Agave Village LLC'!K51+'Brookhaven Estates (bo260)'!K44+'Brookhaven RV Resort'!K40+'Courtly Manor'!K33+'Courtly Manor Park (co669)'!K34+'Cross Creek RV'!K129+'Cross Creek RV Resort (cr994)'!K135+'El Rio De Oro (el289)'!K31+'El Rio del Oro'!K34+'Endless Summer RV Resort'!K52+'Endless Summer RV Resort (en079'!K44+Evergreen!K31+'Far Horizons'!K31+'Far Horizons (fa105)'!K31+'Floridian Sandalwood (fl356)'!K28+'Floridian Sandalwood MHC'!K32+Glenhaven!K36+'Glenhaven Estates (gl317)'!K36+'Harbor Lights (ha310)'!K37+'Harbor Lights MHC'!K35+'Harvest Gate'!K45+'Hunter Run RV Estates'!K86+'Hunters Run RV Estates (hu116)'!K199+'Jade Isle (ja068)'!K28+'Jade Isle MHC'!K30+'Kakusha Estates (ka045)'!K34+'Kakusha MHC'!K33+'Lakeside Village'!K39+'Lakeside Village (la482)'!K41+'Lakewood Village (la481)'!K100+'Lakewood Village MHC LLC'!K120+'Maple Corner'!K53+'Maple Corner (ma490)'!K43+'Marlboro Court (ma489)'!K31+'Marlboro Court MHC LLC'!K31+'May Manor'!K135+'May Manor (ma488)'!K67+'Mobiland by the Sea (mo320)'!K36+'Mobiland By The Sea MHC'!K37+'Moss Landing'!K64+'Moss Landing (mo321)'!K56+'Oak Springs'!K68+'Oak Springs MHC (oa150)'!K44+'Orange Manor East'!K33+'Orange Manor East (or125)'!K36+'Pacific Manor'!K42+'Pacific Manor (pa602)'!K44+Parkhaven!K99+Ridgecrest!K49+Riverest!K43+'Riverview MHRV LLC'!K46+Rosehaven!K111+'Sanctuary RV Resort'!K223+'Shadow Mountain MHC'!K30+Springhaven!K30+'Star Valley Ranch'!K41+Sunhaven!K37+'Sunny Grove'!K36+Tarponaire!K40+'Val Vista RV Resort'!K69+'Webster RV Resort LLC'!K56+'Wekiva Falls RV Resort'!K80+'West Jupiter RV Resort'!K37+'Western Way RV Resort LLC'!K129 | L9: ='Agave Village (ag011)'!L62+'Agave Village LLC'!L51+'Brookhaven Estates (bo260)'!L44+'Brookhaven RV Resort'!L40+'Courtly Manor'!L33+'Courtly Manor Park (co669)'!L34+'Cross Creek RV'!L129+'Cross Creek RV Resort (cr994)'!L135+'El Rio De Oro (el289)'!L31+'El Rio del Oro'!L34+'Endless Summer RV Resort'!L52+'Endless Summer RV Resort (en079'!L44+Evergreen!L31+'Far Horizons'!L31+'Far Horizons (fa105)'!L31+'Floridian Sandalwood (fl356)'!L28+'Floridian Sandalwood MHC'!L32+Glenhaven!L36+'Glenhaven Estates (gl317)'!L36+'Harbor Lights (ha310)'!L37+'Harbor Lights MHC'!L35+'Harvest Gate'!L45+'Hunter Run RV Estates'!L86+'Hunters Run RV Estates (hu116)'!L199+'Jade Isle (ja068)'!L28+'Jade Isle MHC'!L30+'Kakusha Estates (ka045)'!L34+'Kakusha MHC'!L33+'Lakeside Village'!L39+'Lakeside Village (la482)'!L41+'Lakewood Village (la481)'!L100+'Lakewood Village MHC LLC'!L120+'Maple Corner'!L53+'Maple Corner (ma490)'!L43+'Marlboro Court (ma489)'!L31+'Marlboro Court MHC LLC'!L31+'May Manor'!L135+'May Manor (ma488)'!L67+'Mobiland by the Sea (mo320)'!L36+'Mobiland By The Sea MHC'!L37+'Moss Landing'!L64+'Moss Landing (mo321)'!L56+'Oak Springs'!L68+'Oak Springs MHC (oa150)'!L44+'Orange Manor East'!L33+'Orange Manor East (or125)'!L36+'Pacific Manor'!L42+'Pacific Manor (pa602)'!L44+Parkhaven!L99+Ridgecrest!L49+Riverest!L43+'Riverview MHRV LLC'!L46+Rosehaven!L111+'Sanctuary RV Resort'!L223+'Shadow Mountain MHC'!L30+Springhaven!L30+'Star Valley Ranch'!L41+Sunhaven!L37+'Sunny Grove'!L36+Tarponaire!L40+'Val Vista RV Resort'!L69+'Webster RV Resort LLC'!L56+'Wekiva Falls RV Resort'!L80+'West Jupiter RV Resort'!L37+'Western Way RV Resort LLC'!L129 | ... AJ9: ='Agave Village (ag011)'!AJ62+'Agave Village LLC'!AJ51+'Brookhaven Estates (bo260)'!AJ44+'Brookhaven RV Resort'!AJ40+'Courtly Manor'!AJ33+'Courtly Manor Park (co669)'!AJ34+'Cross Creek RV'!AJ129+'Cross Creek RV Resort (cr994)'!AJ135+'El Rio De Oro (el289)'!AJ31+'El Rio del Oro'!AJ34+'Endless Summer RV Resort'!AJ52+'Endless Summer RV Resort (en079'!AJ44+Evergreen!AJ31+'Far Horizons'!AJ31+'Far Horizons (fa105)'!AJ31+'Floridian Sandalwood (fl356)'!AJ28+'Floridian Sandalwood MHC'!AJ32+Glenhaven!AJ36+'Glenhaven Estates (gl317)'!AJ36+'Harbor Lights (ha310)'!AJ37+'Harbor Lights MHC'!AJ35+'Harvest Gate'!AJ45+'Hunter Run RV Estates'!AJ86+'Hunters Run RV Estates (hu116)'!AJ199+'Jade Isle (ja068)'!AJ28+'Jade Isle MHC'!AJ30+'Kakusha Estates (ka045)'!AJ34+'Kakusha MHC'!AJ33+'Lakeside Village'!AJ39+'Lakeside Village (la482)'!AJ41+'Lakewood Village (la481)'!AJ100+'Lakewood Village MHC LLC'!AJ120+'Maple Corner'!AJ53+'Maple Corner (ma490)'!AJ43+'Marlboro Court (ma489)'!AJ31+'Marlboro Court MHC LLC'!AJ31+'May Manor'!AJ135+'May Manor (ma488)'!AJ67+'Mobiland by the Sea (mo320)'!AJ36+'Mobiland By The Sea MHC'!AJ37+'Moss Landing'!AJ64+'Moss Landing (mo321)'!AJ56+'Oak Springs'!AJ68+'Oak Springs MHC (oa150)'!AJ44+'Orange Manor East'!AJ33+'Orange Manor East (or125)'!AJ36+'Pacific Manor'!AJ42+'Pacific Manor (pa602)'!AJ44+Parkhaven!AJ99+Ridgecrest!AJ49+Riverest!AJ43+'Riverview MHRV LLC'!AJ46+Rosehaven!AJ111+'Sanctuary RV Resort'!AJ223+'Shadow Mountain MHC'!AJ30+Springhaven!AJ30+'Star Valley Ranch'!AJ41+Sunhaven!AJ37+'Sunny Grove'!AJ36+Tarponaire!AJ40+'Val Vista RV Resort'!AJ69+'Webster RV Resort LLC'!AJ56+'Wekiva Falls RV Resort'!AJ80+'West Jupiter RV Resort'!AJ37+'Western Way RV Resort LLC'!AJ129
B10: Electricity | E10: ='Agave Village (ag011)'!E63+'Agave Village LLC'!E52+'Brookhaven Estates (bo260)'!E45+'Brookhaven RV Resort'!E41+'Courtly Manor'!E34+'Courtly Manor Park (co669)'!E35+'Cross Creek RV'!E130+'Cross Creek RV Resort (cr994)'!E136+'El Rio De Oro (el289)'!E32+'El Rio del Oro'!E35+'Endless Summer RV Resort'!E53+'Endless Summer RV Resort (en079'!E45+Evergreen!E32+'Far Horizons'!E32+'Far Horizons (fa105)'!E32+'Floridian Sandalwood (fl356)'!E29+'Floridian Sandalwood MHC'!E33+Glenhaven!E37+'Glenhaven Estates (gl317)'!E37+'Harbor Lights (ha310)'!E38+'Harbor Lights MHC'!E36+'Harvest Gate'!E46+'Hunter Run RV Estates'!E87+'Hunters Run RV Estates (hu116)'!E200+'Jade Isle (ja068)'!E29+'Jade Isle MHC'!E31+'Kakusha Estates (ka045)'!E35+'Kakusha MHC'!E34+'Lakeside Village'!E40+'Lakeside Village (la482)'!E42+'Lakewood Village (la481)'!E101+'Lakewood Village MHC LLC'!E121+'Maple Corner'!E54+'Maple Corner (ma490)'!E44+'Marlboro Court (ma489)'!E32+'Marlboro Court MHC LLC'!E32+'May Manor'!E136+'May Manor (ma488)'!E68+'Mobiland by the Sea (mo320)'!E37+'Mobiland By The Sea MHC'!E38+'Moss Landing'!E65+'Moss Landing (mo321)'!E57+'Oak Springs'!E69+'Oak Springs MHC (oa150)'!E45+'Orange Manor East'!E34+'Orange Manor East (or125)'!E37+'Pacific Manor'!E43+'Pacific Manor (pa602)'!E45+Parkhaven!E100+Ridgecrest!E50+Riverest!E44+'Riverview MHRV LLC'!E47+Rosehaven!E112+'Sanctuary RV Resort'!E224+'Shadow Mountain MHC'!E31+Springhaven!E31+'Star Valley Ranch'!E42+Sunhaven!E38+'Sunny Grove'!E37+Tarponaire!E41+'Val Vista RV Resort'!E70+'Webster RV Resort LLC'!E57+'Wekiva Falls RV Resort'!E81+'West Jupiter RV Resort'!E38+'Western Way RV Resort LLC'!E130 | F10: ='Agave Village (ag011)'!F63+'Agave Village LLC'!F52+'Brookhaven Estates (bo260)'!F45+'Brookhaven RV Resort'!F41+'Courtly Manor'!F34+'Courtly Manor Park (co669)'!F35+'Cross Creek RV'!F130+'Cross Creek RV Resort (cr994)'!F136+'El Rio De Oro (el289)'!F32+'El Rio del Oro'!F35+'Endless Summer RV Resort'!F53+'Endless Summer RV Resort (en079'!F45+Evergreen!F32+'Far Horizons'!F32+'Far Horizons (fa105)'!F32+'Floridian Sandalwood (fl356)'!F29+'Floridian Sandalwood MHC'!F33+Glenhaven!F37+'Glenhaven Estates (gl317)'!F37+'Harbor Lights (ha310)'!F38+'Harbor Lights MHC'!F36+'Harvest Gate'!F46+'Hunter Run RV Estates'!F87+'Hunters Run RV Estates (hu116)'!F200+'Jade Isle (ja068)'!F29+'Jade Isle MHC'!F31+'Kakusha Estates (ka045)'!F35+'Kakusha MHC'!F34+'Lakeside Village'!F40+'Lakeside Village (la482)'!F42+'Lakewood Village (la481)'!F101+'Lakewood Village MHC LLC'!F121+'Maple Corner'!F54+'Maple Corner (ma490)'!F44+'Marlboro Court (ma489)'!F32+'Marlboro Court MHC LLC'!F32+'May Manor'!F136+'May Manor (ma488)'!F68+'Mobiland by the Sea (mo320)'!F37+'Mobiland By The Sea MHC'!F38+'Moss Landing'!F65+'Moss Landing (mo321)'!F57+'Oak Springs'!F69+'Oak Springs MHC (oa150)'!F45+'Orange Manor East'!F34+'Orange Manor East (or125)'!F37+'Pacific Manor'!F43+'Pacific Manor (pa602)'!F45+Parkhaven!F100+Ridgecrest!F50+Riverest!F44+'Riverview MHRV LLC'!F47+Rosehaven!F112+'Sanctuary RV Resort'!F224+'Shadow Mountain MHC'!F31+Springhaven!F31+'Star Valley Ranch'!F42+Sunhaven!F38+'Sunny Grove'!F37+Tarponaire!F41+'Val Vista RV Resort'!F70+'Webster RV Resort LLC'!F57+'Wekiva Falls RV Resort'!F81+'West Jupiter RV Resort'!F38+'Western Way RV Resort LLC'!F130 | G10: ='Agave Village (ag011)'!G63+'Agave Village LLC'!G52+'Brookhaven Estates (bo260)'!G45+'Brookhaven RV Resort'!G41+'Courtly Manor'!G34+'Courtly Manor Park (co669)'!G35+'Cross Creek RV'!G130+'Cross Creek RV Resort (cr994)'!G136+'El Rio De Oro (el289)'!G32+'El Rio del Oro'!G35+'Endless Summer RV Resort'!G53+'Endless Summer RV Resort (en079'!G45+Evergreen!G32+'Far Horizons'!G32+'Far Horizons (fa105)'!G32+'Floridian Sandalwood (fl356)'!G29+'Floridian Sandalwood MHC'!G33+Glenhaven!G37+'Glenhaven Estates (gl317)'!G37+'Harbor Lights (ha310)'!G38+'Harbor Lights MHC'!G36+'Harvest Gate'!G46+'Hunter Run RV Estates'!G87+'Hunters Run RV Estates (hu116)'!G200+'Jade Isle (ja068)'!G29+'Jade Isle MHC'!G31+'Kakusha Estates (ka045)'!G35+'Kakusha MHC'!G34+'Lakeside Village'!G40+'Lakeside Village (la482)'!G42+'Lakewood Village (la481)'!G101+'Lakewood Village MHC LLC'!G121+'Maple Corner'!G54+'Maple Corner (ma490)'!G44+'Marlboro Court (ma489)'!G32+'Marlboro Court MHC LLC'!G32+'May Manor'!G136+'May Manor (ma488)'!G68+'Mobiland by the Sea (mo320)'!G37+'Mobiland By The Sea MHC'!G38+'Moss Landing'!G65+'Moss Landing (mo321)'!G57+'Oak Springs'!G69+'Oak Springs MHC (oa150)'!G45+'Orange Manor East'!G34+'Orange Manor East (or125)'!G37+'Pacific Manor'!G43+'Pacific Manor (pa602)'!G45+Parkhaven!G100+Ridgecrest!G50+Riverest!G44+'Riverview MHRV LLC'!G47+Rosehaven!G112+'Sanctuary RV Resort'!G224+'Shadow Mountain MHC'!G31+Springhaven!G31+'Star Valley Ranch'!G42+Sunhaven!G38+'Sunny Grove'!G37+Tarponaire!G41+'Val Vista RV Resort'!G70+'Webster RV Resort LLC'!G57+'Wekiva Falls RV Resort'!G81+'West Jupiter RV Resort'!G38+'Western Way RV Resort LLC'!G130 | H10: ='Agave Village (ag011)'!H63+'Agave Village LLC'!H52+'Brookhaven Estates (bo260)'!H45+'Brookhaven RV Resort'!H41+'Courtly Manor'!H34+'Courtly Manor Park (co669)'!H35+'Cross Creek RV'!H130+'Cross Creek RV Resort (cr994)'!H136+'El Rio De Oro (el289)'!H32+'El Rio del Oro'!H35+'Endless Summer RV Resort'!H53+'Endless Summer RV Resort (en079'!H45+Evergreen!H32+'Far Horizons'!H32+'Far Horizons (fa105)'!H32+'Floridian Sandalwood (fl356)'!H29+'Floridian Sandalwood MHC'!H33+Glenhaven!H37+'Glenhaven Estates (gl317)'!H37+'Harbor Lights (ha310)'!H38+'Harbor Lights MHC'!H36+'Harvest Gate'!H46+'Hunter Run RV Estates'!H87+'Hunters Run RV Estates (hu116)'!H200+'Jade Isle (ja068)'!H29+'Jade Isle MHC'!H31+'Kakusha Estates (ka045)'!H35+'Kakusha MHC'!H34+'Lakeside Village'!H40+'Lakeside Village (la482)'!H42+'Lakewood Village (la481)'!H101+'Lakewood Village MHC LLC'!H121+'Maple Corner'!H54+'Maple Corner (ma490)'!H44+'Marlboro Court (ma489)'!H32+'Marlboro Court MHC LLC'!H32+'May Manor'!H136+'May Manor (ma488)'!H68+'Mobiland by the Sea (mo320)'!H37+'Mobiland By The Sea MHC'!H38+'Moss Landing'!H65+'Moss Landing (mo321)'!H57+'Oak Springs'!H69+'Oak Springs MHC (oa150)'!H45+'Orange Manor East'!H34+'Orange Manor East (or125)'!H37+'Pacific Manor'!H43+'Pacific Manor (pa602)'!H45+Parkhaven!H100+Ridgecrest!H50+Riverest!H44+'Riverview MHRV LLC'!H47+Rosehaven!H112+'Sanctuary RV Resort'!H224+'Shadow Mountain MHC'!H31+Springhaven!H31+'Star Valley Ranch'!H42+Sunhaven!H38+'Sunny Grove'!H37+Tarponaire!H41+'Val Vista RV Resort'!H70+'Webster RV Resort LLC'!H57+'Wekiva Falls RV Resort'!H81+'West Jupiter RV Resort'!H38+'Western Way RV Resort LLC'!H130 | I10: ='Agave Village (ag011)'!I63+'Agave Village LLC'!I52+'Brookhaven Estates (bo260)'!I45+'Brookhaven RV Resort'!I41+'Courtly Manor'!I34+'Courtly Manor Park (co669)'!I35+'Cross Creek RV'!I130+'Cross Creek RV Resort (cr994)'!I136+'El Rio De Oro (el289)'!I32+'El Rio del Oro'!I35+'Endless Summer RV Resort'!I53+'Endless Summer RV Resort (en079'!I45+Evergreen!I32+'Far Horizons'!I32+'Far Horizons (fa105)'!I32+'Floridian Sandalwood (fl356)'!I29+'Floridian Sandalwood MHC'!I33+Glenhaven!I37+'Glenhaven Estates (gl317)'!I37+'Harbor Lights (ha310)'!I38+'Harbor Lights MHC'!I36+'Harvest Gate'!I46+'Hunter Run RV Estates'!I87+'Hunters Run RV Estates (hu116)'!I200+'Jade Isle (ja068)'!I29+'Jade Isle MHC'!I31+'Kakusha Estates (ka045)'!I35+'Kakusha MHC'!I34+'Lakeside Village'!I40+'Lakeside Village (la482)'!I42+'Lakewood Village (la481)'!I101+'Lakewood Village MHC LLC'!I121+'Maple Corner'!I54+'Maple Corner (ma490)'!I44+'Marlboro Court (ma489)'!I32+'Marlboro Court MHC LLC'!I32+'May Manor'!I136+'May Manor (ma488)'!I68+'Mobiland by the Sea (mo320)'!I37+'Mobiland By The Sea MHC'!I38+'Moss Landing'!I65+'Moss Landing (mo321)'!I57+'Oak Springs'!I69+'Oak Springs MHC (oa150)'!I45+'Orange Manor East'!I34+'Orange Manor East (or125)'!I37+'Pacific Manor'!I43+'Pacific Manor (pa602)'!I45+Parkhaven!I100+Ridgecrest!I50+Riverest!I44+'Riverview MHRV LLC'!I47+Rosehaven!I112+'Sanctuary RV Resort'!I224+'Shadow Mountain MHC'!I31+Springhaven!I31+'Star Valley Ranch'!I42+Sunhaven!I38+'Sunny Grove'!I37+Tarponaire!I41+'Val Vista RV Resort'!I70+'Webster RV Resort LLC'!I57+'Wekiva Falls RV Resort'!I81+'West Jupiter RV Resort'!I38+'Western Way RV Resort LLC'!I130 | J10: ='Agave Village (ag011)'!J63+'Agave Village LLC'!J52+'Brookhaven Estates (bo260)'!J45+'Brookhaven RV Resort'!J41+'Courtly Manor'!J34+'Courtly Manor Park (co669)'!J35+'Cross Creek RV'!J130+'Cross Creek RV Resort (cr994)'!J136+'El Rio De Oro (el289)'!J32+'El Rio del Oro'!J35+'Endless Summer RV Resort'!J53+'Endless Summer RV Resort (en079'!J45+Evergreen!J32+'Far Horizons'!J32+'Far Horizons (fa105)'!J32+'Floridian Sandalwood (fl356)'!J29+'Floridian Sandalwood MHC'!J33+Glenhaven!J37+'Glenhaven Estates (gl317)'!J37+'Harbor Lights (ha310)'!J38+'Harbor Lights MHC'!J36+'Harvest Gate'!J46+'Hunter Run RV Estates'!J87+'Hunters Run RV Estates (hu116)'!J200+'Jade Isle (ja068)'!J29+'Jade Isle MHC'!J31+'Kakusha Estates (ka045)'!J35+'Kakusha MHC'!J34+'Lakeside Village'!J40+'Lakeside Village (la482)'!J42+'Lakewood Village (la481)'!J101+'Lakewood Village MHC LLC'!J121+'Maple Corner'!J54+'Maple Corner (ma490)'!J44+'Marlboro Court (ma489)'!J32+'Marlboro Court MHC LLC'!J32+'May Manor'!J136+'May Manor (ma488)'!J68+'Mobiland by the Sea (mo320)'!J37+'Mobiland By The Sea MHC'!J38+'Moss Landing'!J65+'Moss Landing (mo321)'!J57+'Oak Springs'!J69+'Oak Springs MHC (oa150)'!J45+'Orange Manor East'!J34+'Orange Manor East (or125)'!J37+'Pacific Manor'!J43+'Pacific Manor (pa602)'!J45+Parkhaven!J100+Ridgecrest!J50+Riverest!J44+'Riverview MHRV LLC'!J47+Rosehaven!J112+'Sanctuary RV Resort'!J224+'Shadow Mountain MHC'!J31+Springhaven!J31+'Star Valley Ranch'!J42+Sunhaven!J38+'Sunny Grove'!J37+Tarponaire!J41+'Val Vista RV Resort'!J70+'Webster RV Resort LLC'!J57+'Wekiva Falls RV Resort'!J81+'West Jupiter RV Resort'!J38+'Western Way RV Resort LLC'!J130 | K10: ='Agave Village (ag011)'!K63+'Agave Village LLC'!K52+'Brookhaven Estates (bo260)'!K45+'Brookhaven RV Resort'!K41+'Courtly Manor'!K34+'Courtly Manor Park (co669)'!K35+'Cross Creek RV'!K130+'Cross Creek RV Resort (cr994)'!K136+'El Rio De Oro (el289)'!K32+'El Rio del Oro'!K35+'Endless Summer RV Resort'!K53+'Endless Summer RV Resort (en079'!K45+Evergreen!K32+'Far Horizons'!K32+'Far Horizons (fa105)'!K32+'Floridian Sandalwood (fl356)'!K29+'Floridian Sandalwood MHC'!K33+Glenhaven!K37+'Glenhaven Estates (gl317)'!K37+'Harbor Lights (ha310)'!K38+'Harbor Lights MHC'!K36+'Harvest Gate'!K46+'Hunter Run RV Estates'!K87+'Hunters Run RV Estates (hu116)'!K200+'Jade Isle (ja068)'!K29+'Jade Isle MHC'!K31+'Kakusha Estates (ka045)'!K35+'Kakusha MHC'!K34+'Lakeside Village'!K40+'Lakeside Village (la482)'!K42+'Lakewood Village (la481)'!K101+'Lakewood Village MHC LLC'!K121+'Maple Corner'!K54+'Maple Corner (ma490)'!K44+'Marlboro Court (ma489)'!K32+'Marlboro Court MHC LLC'!K32+'May Manor'!K136+'May Manor (ma488)'!K68+'Mobiland by the Sea (mo320)'!K37+'Mobiland By The Sea MHC'!K38+'Moss Landing'!K65+'Moss Landing (mo321)'!K57+'Oak Springs'!K69+'Oak Springs MHC (oa150)'!K45+'Orange Manor East'!K34+'Orange Manor East (or125)'!K37+'Pacific Manor'!K43+'Pacific Manor (pa602)'!K45+Parkhaven!K100+Ridgecrest!K50+Riverest!K44+'Riverview MHRV LLC'!K47+Rosehaven!K112+'Sanctuary RV Resort'!K224+'Shadow Mountain MHC'!K31+Springhaven!K31+'Star Valley Ranch'!K42+Sunhaven!K38+'Sunny Grove'!K37+Tarponaire!K41+'Val Vista RV Resort'!K70+'Webster RV Resort LLC'!K57+'Wekiva Falls RV Resort'!K81+'West Jupiter RV Resort'!K38+'Western Way RV Resort LLC'!K130 | L10: ='Agave Village (ag011)'!L63+'Agave Village LLC'!L52+'Brookhaven Estates (bo260)'!L45+'Brookhaven RV Resort'!L41+'Courtly Manor'!L34+'Courtly Manor Park (co669)'!L35+'Cross Creek RV'!L130+'Cross Creek RV Resort (cr994)'!L136+'El Rio De Oro (el289)'!L32+'El Rio del Oro'!L35+'Endless Summer RV Resort'!L53+'Endless Summer RV Resort (en079'!L45+Evergreen!L32+'Far Horizons'!L32+'Far Horizons (fa105)'!L32+'Floridian Sandalwood (fl356)'!L29+'Floridian Sandalwood MHC'!L33+Glenhaven!L37+'Glenhaven Estates (gl317)'!L37+'Harbor Lights (ha310)'!L38+'Harbor Lights MHC'!L36+'Harvest Gate'!L46+'Hunter Run RV Estates'!L87+'Hunters Run RV Estates (hu116)'!L200+'Jade Isle (ja068)'!L29+'Jade Isle MHC'!L31+'Kakusha Estates (ka045)'!L35+'Kakusha MHC'!L34+'Lakeside Village'!L40+'Lakeside Village (la482)'!L42+'Lakewood Village (la481)'!L101+'Lakewood Village MHC LLC'!L121+'Maple Corner'!L54+'Maple Corner (ma490)'!L44+'Marlboro Court (ma489)'!L32+'Marlboro Court MHC LLC'!L32+'May Manor'!L136+'May Manor (ma488)'!L68+'Mobiland by the Sea (mo320)'!L37+'Mobiland By The Sea MHC'!L38+'Moss Landing'!L65+'Moss Landing (mo321)'!L57+'Oak Springs'!L69+'Oak Springs MHC (oa150)'!L45+'Orange Manor East'!L34+'Orange Manor East (or125)'!L37+'Pacific Manor'!L43+'Pacific Manor (pa602)'!L45+Parkhaven!L100+Ridgecrest!L50+Riverest!L44+'Riverview MHRV LLC'!L47+Rosehaven!L112+'Sanctuary RV Resort'!L224+'Shadow Mountain MHC'!L31+Springhaven!L31+'Star Valley Ranch'!L42+Sunhaven!L38+'Sunny Grove'!L37+Tarponaire!L41+'Val Vista RV Resort'!L70+'Webster RV Resort LLC'!L57+'Wekiva Falls RV Resort'!L81+'West Jupiter RV Resort'!L38+'Western Way RV Resort LLC'!L130 | ... AJ10: ='Agave Village (ag011)'!AJ63+'Agave Village LLC'!AJ52+'Brookhaven Estates (bo260)'!AJ45+'Brookhaven RV Resort'!AJ41+'Courtly Manor'!AJ34+'Courtly Manor Park (co669)'!AJ35+'Cross Creek RV'!AJ130+'Cross Creek RV Resort (cr994)'!AJ136+'El Rio De Oro (el289)'!AJ32+'El Rio del Oro'!AJ35+'Endless Summer RV Resort'!AJ53+'Endless Summer RV Resort (en079'!AJ45+Evergreen!AJ32+'Far Horizons'!AJ32+'Far Horizons (fa105)'!AJ32+'Floridian Sandalwood (fl356)'!AJ29+'Floridian Sandalwood MHC'!AJ33+Glenhaven!AJ37+'Glenhaven Estates (gl317)'!AJ37+'Harbor Lights (ha310)'!AJ38+'Harbor Lights MHC'!AJ36+'Harvest Gate'!AJ46+'Hunter Run RV Estates'!AJ87+'Hunters Run RV Estates (hu116)'!AJ200+'Jade Isle (ja068)'!AJ29+'Jade Isle MHC'!AJ31+'Kakusha Estates (ka045)'!AJ35+'Kakusha MHC'!AJ34+'Lakeside Village'!AJ40+'Lakeside Village (la482)'!AJ42+'Lakewood Village (la481)'!AJ101+'Lakewood Village MHC LLC'!AJ121+'Maple Corner'!AJ54+'Maple Corner (ma490)'!AJ44+'Marlboro Court (ma489)'!AJ32+'Marlboro Court MHC LLC'!AJ32+'May Manor'!AJ136+'May Manor (ma488)'!AJ68+'Mobiland by the Sea (mo320)'!AJ37+'Mobiland By The Sea MHC'!AJ38+'Moss Landing'!AJ65+'Moss Landing (mo321)'!AJ57+'Oak Springs'!AJ69+'Oak Springs MHC (oa150)'!AJ45+'Orange Manor East'!AJ34+'Orange Manor East (or125)'!AJ37+'Pacific Manor'!AJ43+'Pacific Manor (pa602)'!AJ45+Parkhaven!AJ100+Ridgecrest!AJ50+Riverest!AJ44+'Riverview MHRV LLC'!AJ47+Rosehaven!AJ112+'Sanctuary RV Resort'!AJ224+'Shadow Mountain MHC'!AJ31+Springhaven!AJ31+'Star Valley Ranch'!AJ42+Sunhaven!AJ38+'Sunny Grove'!AJ37+Tarponaire!AJ41+'Val Vista RV Resort'!AJ70+'Webster RV Resort LLC'!AJ57+'Wekiva Falls RV Resort'!AJ81+'West Jupiter RV Resort'!AJ38+'Western Way RV Resort LLC'!AJ130
B11: Water | E11: ='Agave Village (ag011)'!E64+'Agave Village LLC'!E53+'Brookhaven Estates (bo260)'!E46+'Brookhaven RV Resort'!E42+'Courtly Manor'!E35+'Courtly Manor Park (co669)'!E36+'Cross Creek RV'!E131+'Cross Creek RV Resort (cr994)'!E137+'El Rio De Oro (el289)'!E33+'El Rio del Oro'!E36+'Endless Summer RV Resort'!E54+'Endless Summer RV Resort (en079'!E46+Evergreen!E33+'Far Horizons'!E33+'Far Horizons (fa105)'!E33+'Floridian Sandalwood (fl356)'!E30+'Floridian Sandalwood MHC'!E34+Glenhaven!E38+'Glenhaven Estates (gl317)'!E38+'Harbor Lights (ha310)'!E39+'Harbor Lights MHC'!E37+'Harvest Gate'!E47+'Hunter Run RV Estates'!E88+'Hunters Run RV Estates (hu116)'!E201+'Jade Isle (ja068)'!E30+'Jade Isle MHC'!E32+'Kakusha Estates (ka045)'!E36+'Kakusha MHC'!E35+'Lakeside Village'!E41+'Lakeside Village (la482)'!E43+'Lakewood Village (la481)'!E102+'Lakewood Village MHC LLC'!E122+'Maple Corner'!E55+'Maple Corner (ma490)'!E45+'Marlboro Court (ma489)'!E33+'Marlboro Court MHC LLC'!E33+'May Manor'!E137+'May Manor (ma488)'!E69+'Mobiland by the Sea (mo320)'!E38+'Mobiland By The Sea MHC'!E39+'Moss Landing'!E66+'Moss Landing (mo321)'!E58+'Oak Springs'!E70+'Oak Springs MHC (oa150)'!E46+'Orange Manor East'!E35+'Orange Manor East (or125)'!E38+'Pacific Manor'!E44+'Pacific Manor (pa602)'!E46+Parkhaven!E101+Ridgecrest!E51+Riverest!E45+'Riverview MHRV LLC'!E48+Rosehaven!E113+'Sanctuary RV Resort'!E225+'Shadow Mountain MHC'!E32+Springhaven!E32+'Star Valley Ranch'!E43+Sunhaven!E39+'Sunny Grove'!E38+Tarponaire!E42+'Val Vista RV Resort'!E71+'Webster RV Resort LLC'!E58+'Wekiva Falls RV Resort'!E82+'West Jupiter RV Resort'!E39+'Western Way RV Resort LLC'!E131 | F11: ='Agave Village (ag011)'!F64+'Agave Village LLC'!F53+'Brookhaven Estates (bo260)'!F46+'Brookhaven RV Resort'!F42+'Courtly Manor'!F35+'Courtly Manor Park (co669)'!F36+'Cross Creek RV'!F131+'Cross Creek RV Resort (cr994)'!F137+'El Rio De Oro (el289)'!F33+'El Rio del Oro'!F36+'Endless Summer RV Resort'!F54+'Endless Summer RV Resort (en079'!F46+Evergreen!F33+'Far Horizons'!F33+'Far Horizons (fa105)'!F33+'Floridian Sandalwood (fl356)'!F30+'Floridian Sandalwood MHC'!F34+Glenhaven!F38+'Glenhaven Estates (gl317)'!F38+'Harbor Lights (ha310)'!F39+'Harbor Lights MHC'!F37+'Harvest Gate'!F47+'Hunter Run RV Estates'!F88+'Hunters Run RV Estates (hu116)'!F201+'Jade Isle (ja068)'!F30+'Jade Isle MHC'!F32+'Kakusha Estates (ka045)'!F36+'Kakusha MHC'!F35+'Lakeside Village'!F41+'Lakeside Village (la482)'!F43+'Lakewood Village (la481)'!F102+'Lakewood Village MHC LLC'!F122+'Maple Corner'!F55+'Maple Corner (ma490)'!F45+'Marlboro Court (ma489)'!F33+'Marlboro Court MHC LLC'!F33+'May Manor'!F137+'May Manor (ma488)'!F69+'Mobiland by the Sea (mo320)'!F38+'Mobiland By The Sea MHC'!F39+'Moss Landing'!F66+'Moss Landing (mo321)'!F58+'Oak Springs'!F70+'Oak Springs MHC (oa150)'!F46+'Orange Manor East'!F35+'Orange Manor East (or125)'!F38+'Pacific Manor'!F44+'Pacific Manor (pa602)'!F46+Parkhaven!F101+Ridgecrest!F51+Riverest!F45+'Riverview MHRV LLC'!F48+Rosehaven!F113+'Sanctuary RV Resort'!F225+'Shadow Mountain MHC'!F32+Springhaven!F32+'Star Valley Ranch'!F43+Sunhaven!F39+'Sunny Grove'!F38+Tarponaire!F42+'Val Vista RV Resort'!F71+'Webster RV Resort LLC'!F58+'Wekiva Falls RV Resort'!F82+'West Jupiter RV Resort'!F39+'Western Way RV Resort LLC'!F131 | G11: ='Agave Village (ag011)'!G64+'Agave Village LLC'!G53+'Brookhaven Estates (bo260)'!G46+'Brookhaven RV Resort'!G42+'Courtly Manor'!G35+'Courtly Manor Park (co669)'!G36+'Cross Creek RV'!G131+'Cross Creek RV Resort (cr994)'!G137+'El Rio De Oro (el289)'!G33+'El Rio del Oro'!G36+'Endless Summer RV Resort'!G54+'Endless Summer RV Resort (en079'!G46+Evergreen!G33+'Far Horizons'!G33+'Far Horizons (fa105)'!G33+'Floridian Sandalwood (fl356)'!G30+'Floridian Sandalwood MHC'!G34+Glenhaven!G38+'Glenhaven Estates (gl317)'!G38+'Harbor Lights (ha310)'!G39+'Harbor Lights MHC'!G37+'Harvest Gate'!G47+'Hunter Run RV Estates'!G88+'Hunters Run RV Estates (hu116)'!G201+'Jade Isle (ja068)'!G30+'Jade Isle MHC'!G32+'Kakusha Estates (ka045)'!G36+'Kakusha MHC'!G35+'Lakeside Village'!G41+'Lakeside Village (la482)'!G43+'Lakewood Village (la481)'!G102+'Lakewood Village MHC LLC'!G122+'Maple Corner'!G55+'Maple Corner (ma490)'!G45+'Marlboro Court (ma489)'!G33+'Marlboro Court MHC LLC'!G33+'May Manor'!G137+'May Manor (ma488)'!G69+'Mobiland by the Sea (mo320)'!G38+'Mobiland By The Sea MHC'!G39+'Moss Landing'!G66+'Moss Landing (mo321)'!G58+'Oak Springs'!G70+'Oak Springs MHC (oa150)'!G46+'Orange Manor East'!G35+'Orange Manor East (or125)'!G38+'Pacific Manor'!G44+'Pacific Manor (pa602)'!G46+Parkhaven!G101+Ridgecrest!G51+Riverest!G45+'Riverview MHRV LLC'!G48+Rosehaven!G113+'Sanctuary RV Resort'!G225+'Shadow Mountain MHC'!G32+Springhaven!G32+'Star Valley Ranch'!G43+Sunhaven!G39+'Sunny Grove'!G38+Tarponaire!G42+'Val Vista RV Resort'!G71+'Webster RV Resort LLC'!G58+'Wekiva Falls RV Resort'!G82+'West Jupiter RV Resort'!G39+'Western Way RV Resort LLC'!G131 | H11: ='Agave Village (ag011)'!H64+'Agave Village LLC'!H53+'Brookhaven Estates (bo260)'!H46+'Brookhaven RV Resort'!H42+'Courtly Manor'!H35+'Courtly Manor Park (co669)'!H36+'Cross Creek RV'!H131+'Cross Creek RV Resort (cr994)'!H137+'El Rio De Oro (el289)'!H33+'El Rio del Oro'!H36+'Endless Summer RV Resort'!H54+'Endless Summer RV Resort (en079'!H46+Evergreen!H33+'Far Horizons'!H33+'Far Horizons (fa105)'!H33+'Floridian Sandalwood (fl356)'!H30+'Floridian Sandalwood MHC'!H34+Glenhaven!H38+'Glenhaven Estates (gl317)'!H38+'Harbor Lights (ha310)'!H39+'Harbor Lights MHC'!H37+'Harvest Gate'!H47+'Hunter Run RV Estates'!H88+'Hunters Run RV Estates (hu116)'!H201+'Jade Isle (ja068)'!H30+'Jade Isle MHC'!H32+'Kakusha Estates (ka045)'!H36+'Kakusha MHC'!H35+'Lakeside Village'!H41+'Lakeside Village (la482)'!H43+'Lakewood Village (la481)'!H102+'Lakewood Village MHC LLC'!H122+'Maple Corner'!H55+'Maple Corner (ma490)'!H45+'Marlboro Court (ma489)'!H33+'Marlboro Court MHC LLC'!H33+'May Manor'!H137+'May Manor (ma488)'!H69+'Mobiland by the Sea (mo320)'!H38+'Mobiland By The Sea MHC'!H39+'Moss Landing'!H66+'Moss Landing (mo321)'!H58+'Oak Springs'!H70+'Oak Springs MHC (oa150)'!H46+'Orange Manor East'!H35+'Orange Manor East (or125)'!H38+'Pacific Manor'!H44+'Pacific Manor (pa602)'!H46+Parkhaven!H101+Ridgecrest!H51+Riverest!H45+'Riverview MHRV LLC'!H48+Rosehaven!H113+'Sanctuary RV Resort'!H225+'Shadow Mountain MHC'!H32+Springhaven!H32+'Star Valley Ranch'!H43+Sunhaven!H39+'Sunny Grove'!H38+Tarponaire!H42+'Val Vista RV Resort'!H71+'Webster RV Resort LLC'!H58+'Wekiva Falls RV Resort'!H82+'West Jupiter RV Resort'!H39+'Western Way RV Resort LLC'!H131 | I11: ='Agave Village (ag011)'!I64+'Agave Village LLC'!I53+'Brookhaven Estates (bo260)'!I46+'Brookhaven RV Resort'!I42+'Courtly Manor'!I35+'Courtly Manor Park (co669)'!I36+'Cross Creek RV'!I131+'Cross Creek RV Resort (cr994)'!I137+'El Rio De Oro (el289)'!I33+'El Rio del Oro'!I36+'Endless Summer RV Resort'!I54+'Endless Summer RV Resort (en079'!I46+Evergreen!I33+'Far Horizons'!I33+'Far Horizons (fa105)'!I33+'Floridian Sandalwood (fl356)'!I30+'Floridian Sandalwood MHC'!I34+Glenhaven!I38+'Glenhaven Estates (gl317)'!I38+'Harbor Lights (ha310)'!I39+'Harbor Lights MHC'!I37+'Harvest Gate'!I47+'Hunter Run RV Estates'!I88+'Hunters Run RV Estates (hu116)'!I201+'Jade Isle (ja068)'!I30+'Jade Isle MHC'!I32+'Kakusha Estates (ka045)'!I36+'Kakusha MHC'!I35+'Lakeside Village'!I41+'Lakeside Village (la482)'!I43+'Lakewood Village (la481)'!I102+'Lakewood Village MHC LLC'!I122+'Maple Corner'!I55+'Maple Corner (ma490)'!I45+'Marlboro Court (ma489)'!I33+'Marlboro Court MHC LLC'!I33+'May Manor'!I137+'May Manor (ma488)'!I69+'Mobiland by the Sea (mo320)'!I38+'Mobiland By The Sea MHC'!I39+'Moss Landing'!I66+'Moss Landing (mo321)'!I58+'Oak Springs'!I70+'Oak Springs MHC (oa150)'!I46+'Orange Manor East'!I35+'Orange Manor East (or125)'!I38+'Pacific Manor'!I44+'Pacific Manor (pa602)'!I46+Parkhaven!I101+Ridgecrest!I51+Riverest!I45+'Riverview MHRV LLC'!I48+Rosehaven!I113+'Sanctuary RV Resort'!I225+'Shadow Mountain MHC'!I32+Springhaven!I32+'Star Valley Ranch'!I43+Sunhaven!I39+'Sunny Grove'!I38+Tarponaire!I42+'Val Vista RV Resort'!I71+'Webster RV Resort LLC'!I58+'Wekiva Falls RV Resort'!I82+'West Jupiter RV Resort'!I39+'Western Way RV Resort LLC'!I131 | J11: ='Agave Village (ag011)'!J64+'Agave Village LLC'!J53+'Brookhaven Estates (bo260)'!J46+'Brookhaven RV Resort'!J42+'Courtly Manor'!J35+'Courtly Manor Park (co669)'!J36+'Cross Creek RV'!J131+'Cross Creek RV Resort (cr994)'!J137+'El Rio De Oro (el289)'!J33+'El Rio del Oro'!J36+'Endless Summer RV Resort'!J54+'Endless Summer RV Resort (en079'!J46+Evergreen!J33+'Far Horizons'!J33+'Far Horizons (fa105)'!J33+'Floridian Sandalwood (fl356)'!J30+'Floridian Sandalwood MHC'!J34+Glenhaven!J38+'Glenhaven Estates (gl317)'!J38+'Harbor Lights (ha310)'!J39+'Harbor Lights MHC'!J37+'Harvest Gate'!J47+'Hunter Run RV Estates'!J88+'Hunters Run RV Estates (hu116)'!J201+'Jade Isle (ja068)'!J30+'Jade Isle MHC'!J32+'Kakusha Estates (ka045)'!J36+'Kakusha MHC'!J35+'Lakeside Village'!J41+'Lakeside Village (la482)'!J43+'Lakewood Village (la481)'!J102+'Lakewood Village MHC LLC'!J122+'Maple Corner'!J55+'Maple Corner (ma490)'!J45+'Marlboro Court (ma489)'!J33+'Marlboro Court MHC LLC'!J33+'May Manor'!J137+'May Manor (ma488)'!J69+'Mobiland by the Sea (mo320)'!J38+'Mobiland By The Sea MHC'!J39+'Moss Landing'!J66+'Moss Landing (mo321)'!J58+'Oak Springs'!J70+'Oak Springs MHC (oa150)'!J46+'Orange Manor East'!J35+'Orange Manor East (or125)'!J38+'Pacific Manor'!J44+'Pacific Manor (pa602)'!J46+Parkhaven!J101+Ridgecrest!J51+Riverest!J45+'Riverview MHRV LLC'!J48+Rosehaven!J113+'Sanctuary RV Resort'!J225+'Shadow Mountain MHC'!J32+Springhaven!J32+'Star Valley Ranch'!J43+Sunhaven!J39+'Sunny Grove'!J38+Tarponaire!J42+'Val Vista RV Resort'!J71+'Webster RV Resort LLC'!J58+'Wekiva Falls RV Resort'!J82+'West Jupiter RV Resort'!J39+'Western Way RV Resort LLC'!J131 | K11: ='Agave Village (ag011)'!K64+'Agave Village LLC'!K53+'Brookhaven Estates (bo260)'!K46+'Brookhaven RV Resort'!K42+'Courtly Manor'!K35+'Courtly Manor Park (co669)'!K36+'Cross Creek RV'!K131+'Cross Creek RV Resort (cr994)'!K137+'El Rio De Oro (el289)'!K33+'El Rio del Oro'!K36+'Endless Summer RV Resort'!K54+'Endless Summer RV Resort (en079'!K46+Evergreen!K33+'Far Horizons'!K33+'Far Horizons (fa105)'!K33+'Floridian Sandalwood (fl356)'!K30+'Floridian Sandalwood MHC'!K34+Glenhaven!K38+'Glenhaven Estates (gl317)'!K38+'Harbor Lights (ha310)'!K39+'Harbor Lights MHC'!K37+'Harvest Gate'!K47+'Hunter Run RV Estates'!K88+'Hunters Run RV Estates (hu116)'!K201+'Jade Isle (ja068)'!K30+'Jade Isle MHC'!K32+'Kakusha Estates (ka045)'!K36+'Kakusha MHC'!K35+'Lakeside Village'!K41+'Lakeside Village (la482)'!K43+'Lakewood Village (la481)'!K102+'Lakewood Village MHC LLC'!K122+'Maple Corner'!K55+'Maple Corner (ma490)'!K45+'Marlboro Court (ma489)'!K33+'Marlboro Court MHC LLC'!K33+'May Manor'!K137+'May Manor (ma488)'!K69+'Mobiland by the Sea (mo320)'!K38+'Mobiland By The Sea MHC'!K39+'Moss Landing'!K66+'Moss Landing (mo321)'!K58+'Oak Springs'!K70+'Oak Springs MHC (oa150)'!K46+'Orange Manor East'!K35+'Orange Manor East (or125)'!K38+'Pacific Manor'!K44+'Pacific Manor (pa602)'!K46+Parkhaven!K101+Ridgecrest!K51+Riverest!K45+'Riverview MHRV LLC'!K48+Rosehaven!K113+'Sanctuary RV Resort'!K225+'Shadow Mountain MHC'!K32+Springhaven!K32+'Star Valley Ranch'!K43+Sunhaven!K39+'Sunny Grove'!K38+Tarponaire!K42+'Val Vista RV Resort'!K71+'Webster RV Resort LLC'!K58+'Wekiva Falls RV Resort'!K82+'West Jupiter RV Resort'!K39+'Western Way RV Resort LLC'!K131 | L11: ='Agave Village (ag011)'!L64+'Agave Village LLC'!L53+'Brookhaven Estates (bo260)'!L46+'Brookhaven RV Resort'!L42+'Courtly Manor'!L35+'Courtly Manor Park (co669)'!L36+'Cross Creek RV'!L131+'Cross Creek RV Resort (cr994)'!L137+'El Rio De Oro (el289)'!L33+'El Rio del Oro'!L36+'Endless Summer RV Resort'!L54+'Endless Summer RV Resort (en079'!L46+Evergreen!L33+'Far Horizons'!L33+'Far Horizons (fa105)'!L33+'Floridian Sandalwood (fl356)'!L30+'Floridian Sandalwood MHC'!L34+Glenhaven!L38+'Glenhaven Estates (gl317)'!L38+'Harbor Lights (ha310)'!L39+'Harbor Lights MHC'!L37+'Harvest Gate'!L47+'Hunter Run RV Estates'!L88+'Hunters Run RV Estates (hu116)'!L201+'Jade Isle (ja068)'!L30+'Jade Isle MHC'!L32+'Kakusha Estates (ka045)'!L36+'Kakusha MHC'!L35+'Lakeside Village'!L41+'Lakeside Village (la482)'!L43+'Lakewood Village (la481)'!L102+'Lakewood Village MHC LLC'!L122+'Maple Corner'!L55+'Maple Corner (ma490)'!L45+'Marlboro Court (ma489)'!L33+'Marlboro Court MHC LLC'!L33+'May Manor'!L137+'May Manor (ma488)'!L69+'Mobiland by the Sea (mo320)'!L38+'Mobiland By The Sea MHC'!L39+'Moss Landing'!L66+'Moss Landing (mo321)'!L58+'Oak Springs'!L70+'Oak Springs MHC (oa150)'!L46+'Orange Manor East'!L35+'Orange Manor East (or125)'!L38+'Pacific Manor'!L44+'Pacific Manor (pa602)'!L46+Parkhaven!L101+Ridgecrest!L51+Riverest!L45+'Riverview MHRV LLC'!L48+Rosehaven!L113+'Sanctuary RV Resort'!L225+'Shadow Mountain MHC'!L32+Springhaven!L32+'Star Valley Ranch'!L43+Sunhaven!L39+'Sunny Grove'!L38+Tarponaire!L42+'Val Vista RV Resort'!L71+'Webster RV Resort LLC'!L58+'Wekiva Falls RV Resort'!L82+'West Jupiter RV Resort'!L39+'Western Way RV Resort LLC'!L131 | ... AJ11: ='Agave Village (ag011)'!AJ64+'Agave Village LLC'!AJ53+'Brookhaven Estates (bo260)'!AJ46+'Brookhaven RV Resort'!AJ42+'Courtly Manor'!AJ35+'Courtly Manor Park (co669)'!AJ36+'Cross Creek RV'!AJ131+'Cross Creek RV Resort (cr994)'!AJ137+'El Rio De Oro (el289)'!AJ33+'El Rio del Oro'!AJ36+'Endless Summer RV Resort'!AJ54+'Endless Summer RV Resort (en079'!AJ46+Evergreen!AJ33+'Far Horizons'!AJ33+'Far Horizons (fa105)'!AJ33+'Floridian Sandalwood (fl356)'!AJ30+'Floridian Sandalwood MHC'!AJ34+Glenhaven!AJ38+'Glenhaven Estates (gl317)'!AJ38+'Harbor Lights (ha310)'!AJ39+'Harbor Lights MHC'!AJ37+'Harvest Gate'!AJ47+'Hunter Run RV Estates'!AJ88+'Hunters Run RV Estates (hu116)'!AJ201+'Jade Isle (ja068)'!AJ30+'Jade Isle MHC'!AJ32+'Kakusha Estates (ka045)'!AJ36+'Kakusha MHC'!AJ35+'Lakeside Village'!AJ41+'Lakeside Village (la482)'!AJ43+'Lakewood Village (la481)'!AJ102+'Lakewood Village MHC LLC'!AJ122+'Maple Corner'!AJ55+'Maple Corner (ma490)'!AJ45+'Marlboro Court (ma489)'!AJ33+'Marlboro Court MHC LLC'!AJ33+'May Manor'!AJ137+'May Manor (ma488)'!AJ69+'Mobiland by the Sea (mo320)'!AJ38+'Mobiland By The Sea MHC'!AJ39+'Moss Landing'!AJ66+'Moss Landing (mo321)'!AJ58+'Oak Springs'!AJ70+'Oak Springs MHC (oa150)'!AJ46+'Orange Manor East'!AJ35+'Orange Manor East (or125)'!AJ38+'Pacific Manor'!AJ44+'Pacific Manor (pa602)'!AJ46+Parkhaven!AJ101+Ridgecrest!AJ51+Riverest!AJ45+'Riverview MHRV LLC'!AJ48+Rosehaven!AJ113+'Sanctuary RV Resort'!AJ225+'Shadow Mountain MHC'!AJ32+Springhaven!AJ32+'Star Valley Ranch'!AJ43+Sunhaven!AJ39+'Sunny Grove'!AJ38+Tarponaire!AJ42+'Val Vista RV Resort'!AJ71+'Webster RV Resort LLC'!AJ58+'Wekiva Falls RV Resort'!AJ82+'West Jupiter RV Resort'!AJ39+'Western Way RV Resort LLC'!AJ131
